[2024-01-05T22:09:48.600+0300] {taskinstance.py:1090} INFO - Dependencies all met for dep_context=non-requeueable deps ti=<TaskInstance: test_mlflow_server.test_mlflow_server scheduled__2024-01-01T01:30:00+00:00 [queued]>
[2024-01-05T22:09:48.606+0300] {taskinstance.py:1090} INFO - Dependencies all met for dep_context=requeueable deps ti=<TaskInstance: test_mlflow_server.test_mlflow_server scheduled__2024-01-01T01:30:00+00:00 [queued]>
[2024-01-05T22:09:48.606+0300] {taskinstance.py:1288} INFO - 
--------------------------------------------------------------------------------
[2024-01-05T22:09:48.606+0300] {taskinstance.py:1289} INFO - Starting attempt 2 of 2
[2024-01-05T22:09:48.606+0300] {taskinstance.py:1290} INFO - 
--------------------------------------------------------------------------------
[2024-01-05T22:09:48.619+0300] {taskinstance.py:1309} INFO - Executing <Task(PythonOperator): test_mlflow_server> on 2024-01-01 01:30:00+00:00
[2024-01-05T22:09:48.622+0300] {standard_task_runner.py:55} INFO - Started process 200949 to run task
[2024-01-05T22:09:48.627+0300] {standard_task_runner.py:82} INFO - Running: ['airflow', 'tasks', 'run', 'test_mlflow_server', 'test_mlflow_server', 'scheduled__2024-01-01T01:30:00+00:00', '--job-id', '538', '--raw', '--subdir', 'DAGS_FOLDER/tests.py', '--cfg-path', '/tmp/tmpd787w3o7']
[2024-01-05T22:09:48.628+0300] {standard_task_runner.py:83} INFO - Job 538: Subtask test_mlflow_server
[2024-01-05T22:09:48.780+0300] {task_command.py:389} INFO - Running <TaskInstance: test_mlflow_server.test_mlflow_server scheduled__2024-01-01T01:30:00+00:00 [running]> on host prod-srv
[2024-01-05T22:09:48.872+0300] {taskinstance.py:1516} INFO - Exporting the following env vars:
AIRFLOW_CTX_DAG_OWNER=admin
AIRFLOW_CTX_DAG_ID=test_mlflow_server
AIRFLOW_CTX_TASK_ID=test_mlflow_server
AIRFLOW_CTX_EXECUTION_DATE=2024-01-01T01:30:00+00:00
AIRFLOW_CTX_TRY_NUMBER=2
AIRFLOW_CTX_DAG_RUN_ID=scheduled__2024-01-01T01:30:00+00:00
[2024-01-05T22:09:48.876+0300] {taskinstance.py:1776} ERROR - Task failed with exception
Traceback (most recent call last):
  File "/home/igor/mlops_4/venv4/lib/python3.10/site-packages/airflow/operators/python.py", line 175, in execute
    return_value = self.execute_callable()
  File "/home/igor/mlops_4/venv4/lib/python3.10/site-packages/airflow/operators/python.py", line 192, in execute_callable
    return self.python_callable(*self.op_args, **self.op_kwargs)
  File "/home/igor/mlops_4/airflow/dags/tests.py", line 10, in test_url
    assert r.status_code == 303
AssertionError
[2024-01-05T22:09:48.898+0300] {taskinstance.py:1327} INFO - Marking task as FAILED. dag_id=test_mlflow_server, task_id=test_mlflow_server, execution_date=20240101T013000, start_date=20240105T190948, end_date=20240105T190948
[2024-01-05T22:09:48.911+0300] {standard_task_runner.py:100} ERROR - Failed to execute job 538 for task test_mlflow_server (; 200949)
[2024-01-05T22:09:48.920+0300] {local_task_job.py:212} INFO - Task exited with return code 1
[2024-01-05T22:09:48.947+0300] {taskinstance.py:2596} INFO - 0 downstream tasks scheduled from follow-on schedule check
