[2024-01-05T22:04:27.239+0300] {taskinstance.py:1090} INFO - Dependencies all met for dep_context=non-requeueable deps ti=<TaskInstance: test_mlflow_server.test_mlflow_server scheduled__2024-01-01T00:30:00+00:00 [queued]>
[2024-01-05T22:04:27.245+0300] {taskinstance.py:1090} INFO - Dependencies all met for dep_context=requeueable deps ti=<TaskInstance: test_mlflow_server.test_mlflow_server scheduled__2024-01-01T00:30:00+00:00 [queued]>
[2024-01-05T22:04:27.245+0300] {taskinstance.py:1288} INFO - 
--------------------------------------------------------------------------------
[2024-01-05T22:04:27.245+0300] {taskinstance.py:1289} INFO - Starting attempt 2 of 2
[2024-01-05T22:04:27.245+0300] {taskinstance.py:1290} INFO - 
--------------------------------------------------------------------------------
[2024-01-05T22:04:27.256+0300] {taskinstance.py:1309} INFO - Executing <Task(PythonOperator): test_mlflow_server> on 2024-01-01 00:30:00+00:00
[2024-01-05T22:04:27.259+0300] {standard_task_runner.py:55} INFO - Started process 188740 to run task
[2024-01-05T22:04:27.264+0300] {standard_task_runner.py:82} INFO - Running: ['airflow', 'tasks', 'run', 'test_mlflow_server', 'test_mlflow_server', 'scheduled__2024-01-01T00:30:00+00:00', '--job-id', '488', '--raw', '--subdir', 'DAGS_FOLDER/tests.py', '--cfg-path', '/tmp/tmpohik6ol3']
[2024-01-05T22:04:27.265+0300] {standard_task_runner.py:83} INFO - Job 488: Subtask test_mlflow_server
[2024-01-05T22:04:27.354+0300] {task_command.py:389} INFO - Running <TaskInstance: test_mlflow_server.test_mlflow_server scheduled__2024-01-01T00:30:00+00:00 [running]> on host prod-srv
[2024-01-05T22:04:27.448+0300] {taskinstance.py:1516} INFO - Exporting the following env vars:
AIRFLOW_CTX_DAG_OWNER=admin
AIRFLOW_CTX_DAG_ID=test_mlflow_server
AIRFLOW_CTX_TASK_ID=test_mlflow_server
AIRFLOW_CTX_EXECUTION_DATE=2024-01-01T00:30:00+00:00
AIRFLOW_CTX_TRY_NUMBER=2
AIRFLOW_CTX_DAG_RUN_ID=scheduled__2024-01-01T00:30:00+00:00
[2024-01-05T22:04:27.454+0300] {taskinstance.py:1776} ERROR - Task failed with exception
Traceback (most recent call last):
  File "/home/igor/mlops_4/venv4/lib/python3.10/site-packages/airflow/operators/python.py", line 175, in execute
    return_value = self.execute_callable()
  File "/home/igor/mlops_4/venv4/lib/python3.10/site-packages/airflow/operators/python.py", line 192, in execute_callable
    return self.python_callable(*self.op_args, **self.op_kwargs)
  File "/home/igor/mlops_4/airflow/dags/tests.py", line 10, in test_url
    assert r.status_code == 303
AssertionError
[2024-01-05T22:04:27.481+0300] {taskinstance.py:1327} INFO - Marking task as FAILED. dag_id=test_mlflow_server, task_id=test_mlflow_server, execution_date=20240101T003000, start_date=20240105T190427, end_date=20240105T190427
[2024-01-05T22:04:27.489+0300] {standard_task_runner.py:100} ERROR - Failed to execute job 488 for task test_mlflow_server (; 188740)
[2024-01-05T22:04:27.519+0300] {local_task_job.py:212} INFO - Task exited with return code 1
[2024-01-05T22:04:27.556+0300] {taskinstance.py:2596} INFO - 0 downstream tasks scheduled from follow-on schedule check
